[2025-04-21T01:30:41.156-0300] {local_task_job_runner.py:123} INFO - ::group::Pre task execution logs
[2025-04-21T01:30:41.171-0300] {taskinstance.py:2613} INFO - Dependencies all met for dep_context=non-requeueable deps ti=<TaskInstance: Web_Scraping.wait_1 scheduled__2023-01-01T00:00:00+00:00 [queued]>
[2025-04-21T01:30:41.179-0300] {taskinstance.py:2613} INFO - Dependencies all met for dep_context=requeueable deps ti=<TaskInstance: Web_Scraping.wait_1 scheduled__2023-01-01T00:00:00+00:00 [queued]>
[2025-04-21T01:30:41.180-0300] {taskinstance.py:2866} INFO - Starting attempt 1 of 2
[2025-04-21T01:30:41.205-0300] {taskinstance.py:2889} INFO - Executing <Task(PythonOperator): wait_1> on 2023-01-01 00:00:00+00:00
[2025-04-21T01:30:41.209-0300] {standard_task_runner.py:72} INFO - Started process 7382 to run task
[2025-04-21T01:30:41.213-0300] {standard_task_runner.py:104} INFO - Running: ['airflow', 'tasks', 'run', 'Web_Scraping', 'wait_1', 'scheduled__2023-01-01T00:00:00+00:00', '--job-id', '9', '--raw', '--subdir', 'DAGS_FOLDER/Ifood_case.py', '--cfg-path', '/tmp/tmpkrfzxcqa']
[2025-04-21T01:30:41.214-0300] {standard_task_runner.py:105} INFO - Job 9: Subtask wait_1
[2025-04-21T01:30:41.258-0300] {task_command.py:467} INFO - Running <TaskInstance: Web_Scraping.wait_1 scheduled__2023-01-01T00:00:00+00:00 [running]> on host DESKTOP-1GIT60U.
[2025-04-21T01:30:41.354-0300] {taskinstance.py:3132} INFO - Exporting env vars: AIRFLOW_CTX_DAG_EMAIL='airflow@example.com' AIRFLOW_CTX_DAG_OWNER='airflow' AIRFLOW_CTX_DAG_ID='Web_Scraping' AIRFLOW_CTX_TASK_ID='wait_1' AIRFLOW_CTX_EXECUTION_DATE='2023-01-01T00:00:00+00:00' AIRFLOW_CTX_TRY_NUMBER='1' AIRFLOW_CTX_DAG_RUN_ID='scheduled__2023-01-01T00:00:00+00:00'
[2025-04-21T01:30:41.355-0300] {taskinstance.py:731} INFO - ::endgroup::
[2025-04-21T01:31:08.608-0300] {local_task_job_runner.py:346} WARNING - State of this instance has been externally set to None. Terminating instance.
[2025-04-21T01:31:08.612-0300] {local_task_job_runner.py:245} INFO - ::endgroup::
[2025-04-21T01:31:08.618-0300] {process_utils.py:132} INFO - Sending 15 to group 7382. PIDs of all processes in the group: [7382]
[2025-04-21T01:31:08.619-0300] {process_utils.py:87} INFO - Sending the signal 15 to group 7382
[2025-04-21T01:31:08.619-0300] {taskinstance.py:3093} ERROR - Received SIGTERM. Terminating subprocesses.
[2025-04-21T01:31:08.636-0300] {taskinstance.py:3311} ERROR - Task failed with exception
Traceback (most recent call last):
  File "/home/lenovo/miniconda3/envs/worker/lib/python3.12/site-packages/airflow/models/taskinstance.py", line 767, in _execute_task
    result = _execute_callable(context=context, **execute_callable_kwargs)
             ^^^^^^^^^^^^^^^^^^^^^^^^^^^^^^^^^^^^^^^^^^^^^^^^^^^^^^^^^^^^^
  File "/home/lenovo/miniconda3/envs/worker/lib/python3.12/site-packages/airflow/models/taskinstance.py", line 733, in _execute_callable
    return ExecutionCallableRunner(
           ^^^^^^^^^^^^^^^^^^^^^^^^
  File "/home/lenovo/miniconda3/envs/worker/lib/python3.12/site-packages/airflow/utils/operator_helpers.py", line 252, in run
    return self.func(*args, **kwargs)
           ^^^^^^^^^^^^^^^^^^^^^^^^^^
  File "/home/lenovo/miniconda3/envs/worker/lib/python3.12/site-packages/airflow/models/baseoperator.py", line 422, in wrapper
    return func(self, *args, **kwargs)
           ^^^^^^^^^^^^^^^^^^^^^^^^^^^
  File "/home/lenovo/miniconda3/envs/worker/lib/python3.12/site-packages/airflow/operators/python.py", line 238, in execute
    return_value = self.execute_callable()
                   ^^^^^^^^^^^^^^^^^^^^^^^
  File "/home/lenovo/miniconda3/envs/worker/lib/python3.12/site-packages/airflow/operators/python.py", line 256, in execute_callable
    return runner.run(*self.op_args, **self.op_kwargs)
           ^^^^^^^^^^^^^^^^^^^^^^^^^^^^^^^^^^^^^^^^^^^
  File "/home/lenovo/miniconda3/envs/worker/lib/python3.12/site-packages/airflow/utils/operator_helpers.py", line 252, in run
    return self.func(*args, **kwargs)
           ^^^^^^^^^^^^^^^^^^^^^^^^^^
  File "/home/lenovo/airflow/dags/Ifood_case.py", line 55, in espera
    time.sleep(60)
  File "/home/lenovo/miniconda3/envs/worker/lib/python3.12/site-packages/airflow/models/taskinstance.py", line 3095, in signal_handler
    raise AirflowTaskTerminated("Task received SIGTERM signal")
airflow.exceptions.AirflowTaskTerminated: Task received SIGTERM signal
[2025-04-21T01:31:08.649-0300] {taskinstance.py:1225} INFO - Marking task as UP_FOR_RETRY. dag_id=Web_Scraping, task_id=wait_1, run_id=scheduled__2023-01-01T00:00:00+00:00, execution_date=20230101T000000, start_date=20250421T043041, end_date=20250421T043108
[2025-04-21T01:31:08.673-0300] {taskinstance.py:340} INFO - ::group::Post task execution logs
[2025-04-21T01:31:08.675-0300] {standard_task_runner.py:124} ERROR - Failed to execute job 9 for task wait_1 ((sqlite3.IntegrityError) FOREIGN KEY constraint failed
[SQL: INSERT INTO task_fail (task_id, dag_id, run_id, map_index, start_date, end_date, duration) VALUES (?, ?, ?, ?, ?, ?, ?)]
[parameters: ('wait_1', 'Web_Scraping', 'scheduled__2023-01-01T00:00:00+00:00', -1, '2025-04-21 04:30:41.172049', '2025-04-21 04:31:08.647977', 27)]
(Background on this error at: https://sqlalche.me/e/14/gkpj); 7382)
Traceback (most recent call last):
  File "/home/lenovo/miniconda3/envs/worker/lib/python3.12/site-packages/airflow/models/taskinstance.py", line 273, in _run_raw_task
    TaskInstance._execute_task_with_callbacks(
  File "/home/lenovo/miniconda3/envs/worker/lib/python3.12/site-packages/airflow/models/taskinstance.py", line 3159, in _execute_task_with_callbacks
    result = self._execute_task(context, task_orig)
             ^^^^^^^^^^^^^^^^^^^^^^^^^^^^^^^^^^^^^^
  File "/home/lenovo/miniconda3/envs/worker/lib/python3.12/site-packages/airflow/models/taskinstance.py", line 3183, in _execute_task
    return _execute_task(self, context, task_orig)
           ^^^^^^^^^^^^^^^^^^^^^^^^^^^^^^^^^^^^^^^
  File "/home/lenovo/miniconda3/envs/worker/lib/python3.12/site-packages/airflow/models/taskinstance.py", line 767, in _execute_task
    result = _execute_callable(context=context, **execute_callable_kwargs)
             ^^^^^^^^^^^^^^^^^^^^^^^^^^^^^^^^^^^^^^^^^^^^^^^^^^^^^^^^^^^^^
  File "/home/lenovo/miniconda3/envs/worker/lib/python3.12/site-packages/airflow/models/taskinstance.py", line 733, in _execute_callable
    return ExecutionCallableRunner(
           ^^^^^^^^^^^^^^^^^^^^^^^^
  File "/home/lenovo/miniconda3/envs/worker/lib/python3.12/site-packages/airflow/utils/operator_helpers.py", line 252, in run
    return self.func(*args, **kwargs)
           ^^^^^^^^^^^^^^^^^^^^^^^^^^
  File "/home/lenovo/miniconda3/envs/worker/lib/python3.12/site-packages/airflow/models/baseoperator.py", line 422, in wrapper
    return func(self, *args, **kwargs)
           ^^^^^^^^^^^^^^^^^^^^^^^^^^^
  File "/home/lenovo/miniconda3/envs/worker/lib/python3.12/site-packages/airflow/operators/python.py", line 238, in execute
    return_value = self.execute_callable()
                   ^^^^^^^^^^^^^^^^^^^^^^^
  File "/home/lenovo/miniconda3/envs/worker/lib/python3.12/site-packages/airflow/operators/python.py", line 256, in execute_callable
    return runner.run(*self.op_args, **self.op_kwargs)
           ^^^^^^^^^^^^^^^^^^^^^^^^^^^^^^^^^^^^^^^^^^^
  File "/home/lenovo/miniconda3/envs/worker/lib/python3.12/site-packages/airflow/utils/operator_helpers.py", line 252, in run
    return self.func(*args, **kwargs)
           ^^^^^^^^^^^^^^^^^^^^^^^^^^
  File "/home/lenovo/airflow/dags/Ifood_case.py", line 55, in espera
    time.sleep(60)
  File "/home/lenovo/miniconda3/envs/worker/lib/python3.12/site-packages/airflow/models/taskinstance.py", line 3095, in signal_handler
    raise AirflowTaskTerminated("Task received SIGTERM signal")
airflow.exceptions.AirflowTaskTerminated: Task received SIGTERM signal

During handling of the above exception, another exception occurred:

Traceback (most recent call last):
  File "/home/lenovo/miniconda3/envs/worker/lib/python3.12/site-packages/sqlalchemy/engine/base.py", line 1910, in _execute_context
    self.dialect.do_execute(
  File "/home/lenovo/miniconda3/envs/worker/lib/python3.12/site-packages/sqlalchemy/engine/default.py", line 736, in do_execute
    cursor.execute(statement, parameters)
sqlite3.IntegrityError: FOREIGN KEY constraint failed

The above exception was the direct cause of the following exception:

Traceback (most recent call last):
  File "/home/lenovo/miniconda3/envs/worker/lib/python3.12/site-packages/airflow/task/task_runner/standard_task_runner.py", line 117, in _start_by_fork
    ret = args.func(args, dag=self.dag)
          ^^^^^^^^^^^^^^^^^^^^^^^^^^^^^
  File "/home/lenovo/miniconda3/envs/worker/lib/python3.12/site-packages/airflow/cli/cli_config.py", line 49, in command
    return func(*args, **kwargs)
           ^^^^^^^^^^^^^^^^^^^^^
  File "/home/lenovo/miniconda3/envs/worker/lib/python3.12/site-packages/airflow/utils/cli.py", line 116, in wrapper
    return f(*args, **kwargs)
           ^^^^^^^^^^^^^^^^^^
  File "/home/lenovo/miniconda3/envs/worker/lib/python3.12/site-packages/airflow/cli/commands/task_command.py", line 483, in task_run
    task_return_code = _run_task_by_selected_method(args, _dag, ti)
                       ^^^^^^^^^^^^^^^^^^^^^^^^^^^^^^^^^^^^^^^^^^^^
  File "/home/lenovo/miniconda3/envs/worker/lib/python3.12/site-packages/airflow/cli/commands/task_command.py", line 256, in _run_task_by_selected_method
    return _run_raw_task(args, ti)
           ^^^^^^^^^^^^^^^^^^^^^^^
  File "/home/lenovo/miniconda3/envs/worker/lib/python3.12/site-packages/airflow/cli/commands/task_command.py", line 341, in _run_raw_task
    return ti._run_raw_task(
           ^^^^^^^^^^^^^^^^^
  File "/home/lenovo/miniconda3/envs/worker/lib/python3.12/site-packages/airflow/utils/session.py", line 97, in wrapper
    return func(*args, session=session, **kwargs)
           ^^^^^^^^^^^^^^^^^^^^^^^^^^^^^^^^^^^^^^
  File "/home/lenovo/miniconda3/envs/worker/lib/python3.12/site-packages/airflow/models/taskinstance.py", line 3005, in _run_raw_task
    return _run_raw_task(
           ^^^^^^^^^^^^^^
  File "/home/lenovo/miniconda3/envs/worker/lib/python3.12/site-packages/airflow/models/taskinstance.py", line 327, in _run_raw_task
    ti.handle_failure(e, test_mode, context, session=session)
  File "/home/lenovo/miniconda3/envs/worker/lib/python3.12/site-packages/airflow/utils/session.py", line 94, in wrapper
    return func(*args, **kwargs)
           ^^^^^^^^^^^^^^^^^^^^^
  File "/home/lenovo/miniconda3/envs/worker/lib/python3.12/site-packages/airflow/models/taskinstance.py", line 3428, in handle_failure
    _handle_failure(
  File "/home/lenovo/miniconda3/envs/worker/lib/python3.12/site-packages/airflow/utils/session.py", line 94, in wrapper
    return func(*args, **kwargs)
           ^^^^^^^^^^^^^^^^^^^^^
  File "/home/lenovo/miniconda3/envs/worker/lib/python3.12/site-packages/airflow/api_internal/internal_api_call.py", line 166, in wrapper
    return func(*args, **kwargs)
           ^^^^^^^^^^^^^^^^^^^^^
  File "/home/lenovo/miniconda3/envs/worker/lib/python3.12/site-packages/airflow/models/taskinstance.py", line 1243, in _handle_failure
    TaskInstance.save_to_db(failure_context["ti"], session)
  File "/home/lenovo/miniconda3/envs/worker/lib/python3.12/site-packages/airflow/api_internal/internal_api_call.py", line 166, in wrapper
    return func(*args, **kwargs)
           ^^^^^^^^^^^^^^^^^^^^^
  File "/home/lenovo/miniconda3/envs/worker/lib/python3.12/site-packages/airflow/utils/session.py", line 94, in wrapper
    return func(*args, **kwargs)
           ^^^^^^^^^^^^^^^^^^^^^
  File "/home/lenovo/miniconda3/envs/worker/lib/python3.12/site-packages/airflow/models/taskinstance.py", line 3400, in save_to_db
    session.flush()
  File "/home/lenovo/miniconda3/envs/worker/lib/python3.12/site-packages/sqlalchemy/orm/session.py", line 3449, in flush
    self._flush(objects)
  File "/home/lenovo/miniconda3/envs/worker/lib/python3.12/site-packages/sqlalchemy/orm/session.py", line 3588, in _flush
    with util.safe_reraise():
         ^^^^^^^^^^^^^^^^^^^
  File "/home/lenovo/miniconda3/envs/worker/lib/python3.12/site-packages/sqlalchemy/util/langhelpers.py", line 70, in __exit__
    compat.raise_(
  File "/home/lenovo/miniconda3/envs/worker/lib/python3.12/site-packages/sqlalchemy/util/compat.py", line 211, in raise_
    raise exception
  File "/home/lenovo/miniconda3/envs/worker/lib/python3.12/site-packages/sqlalchemy/orm/session.py", line 3549, in _flush
    flush_context.execute()
  File "/home/lenovo/miniconda3/envs/worker/lib/python3.12/site-packages/sqlalchemy/orm/unitofwork.py", line 456, in execute
    rec.execute(self)
  File "/home/lenovo/miniconda3/envs/worker/lib/python3.12/site-packages/sqlalchemy/orm/unitofwork.py", line 630, in execute
    util.preloaded.orm_persistence.save_obj(
  File "/home/lenovo/miniconda3/envs/worker/lib/python3.12/site-packages/sqlalchemy/orm/persistence.py", line 245, in save_obj
    _emit_insert_statements(
  File "/home/lenovo/miniconda3/envs/worker/lib/python3.12/site-packages/sqlalchemy/orm/persistence.py", line 1238, in _emit_insert_statements
    result = connection._execute_20(
             ^^^^^^^^^^^^^^^^^^^^^^^
  File "/home/lenovo/miniconda3/envs/worker/lib/python3.12/site-packages/sqlalchemy/engine/base.py", line 1710, in _execute_20
    return meth(self, args_10style, kwargs_10style, execution_options)
           ^^^^^^^^^^^^^^^^^^^^^^^^^^^^^^^^^^^^^^^^^^^^^^^^^^^^^^^^^^^
  File "/home/lenovo/miniconda3/envs/worker/lib/python3.12/site-packages/sqlalchemy/sql/elements.py", line 334, in _execute_on_connection
    return connection._execute_clauseelement(
           ^^^^^^^^^^^^^^^^^^^^^^^^^^^^^^^^^^
  File "/home/lenovo/miniconda3/envs/worker/lib/python3.12/site-packages/sqlalchemy/engine/base.py", line 1577, in _execute_clauseelement
    ret = self._execute_context(
          ^^^^^^^^^^^^^^^^^^^^^^
  File "/home/lenovo/miniconda3/envs/worker/lib/python3.12/site-packages/sqlalchemy/engine/base.py", line 1953, in _execute_context
    self._handle_dbapi_exception(
  File "/home/lenovo/miniconda3/envs/worker/lib/python3.12/site-packages/sqlalchemy/engine/base.py", line 2134, in _handle_dbapi_exception
    util.raise_(
  File "/home/lenovo/miniconda3/envs/worker/lib/python3.12/site-packages/sqlalchemy/util/compat.py", line 211, in raise_
    raise exception
  File "/home/lenovo/miniconda3/envs/worker/lib/python3.12/site-packages/sqlalchemy/engine/base.py", line 1910, in _execute_context
    self.dialect.do_execute(
  File "/home/lenovo/miniconda3/envs/worker/lib/python3.12/site-packages/sqlalchemy/engine/default.py", line 736, in do_execute
    cursor.execute(statement, parameters)
sqlalchemy.exc.IntegrityError: (sqlite3.IntegrityError) FOREIGN KEY constraint failed
[SQL: INSERT INTO task_fail (task_id, dag_id, run_id, map_index, start_date, end_date, duration) VALUES (?, ?, ?, ?, ?, ?, ?)]
[parameters: ('wait_1', 'Web_Scraping', 'scheduled__2023-01-01T00:00:00+00:00', -1, '2025-04-21 04:30:41.172049', '2025-04-21 04:31:08.647977', 27)]
(Background on this error at: https://sqlalche.me/e/14/gkpj)
[2025-04-21T01:31:08.712-0300] {process_utils.py:80} INFO - Process psutil.Process(pid=7382, status='terminated', exitcode=1, started='01:30:41') (7382) terminated with exit code 1
[2025-04-21T01:31:26.120-0300] {local_task_job_runner.py:123} INFO - ::group::Pre task execution logs
[2025-04-21T01:31:26.135-0300] {taskinstance.py:2613} INFO - Dependencies all met for dep_context=non-requeueable deps ti=<TaskInstance: Web_Scraping.wait_1 scheduled__2023-01-01T00:00:00+00:00 [queued]>
[2025-04-21T01:31:26.144-0300] {taskinstance.py:2613} INFO - Dependencies all met for dep_context=requeueable deps ti=<TaskInstance: Web_Scraping.wait_1 scheduled__2023-01-01T00:00:00+00:00 [queued]>
[2025-04-21T01:31:26.145-0300] {taskinstance.py:2866} INFO - Starting attempt 1 of 2
[2025-04-21T01:31:26.173-0300] {taskinstance.py:2889} INFO - Executing <Task(PythonOperator): wait_1> on 2023-01-01 00:00:00+00:00
[2025-04-21T01:31:26.177-0300] {standard_task_runner.py:72} INFO - Started process 7491 to run task
[2025-04-21T01:31:26.180-0300] {standard_task_runner.py:104} INFO - Running: ['airflow', 'tasks', 'run', 'Web_Scraping', 'wait_1', 'scheduled__2023-01-01T00:00:00+00:00', '--job-id', '12', '--raw', '--subdir', 'DAGS_FOLDER/Ifood_case.py', '--cfg-path', '/tmp/tmplzg8ifwk']
[2025-04-21T01:31:26.181-0300] {standard_task_runner.py:105} INFO - Job 12: Subtask wait_1
[2025-04-21T01:31:26.230-0300] {task_command.py:467} INFO - Running <TaskInstance: Web_Scraping.wait_1 scheduled__2023-01-01T00:00:00+00:00 [running]> on host DESKTOP-1GIT60U.
[2025-04-21T01:31:26.317-0300] {taskinstance.py:3132} INFO - Exporting env vars: AIRFLOW_CTX_DAG_EMAIL='airflow@example.com' AIRFLOW_CTX_DAG_OWNER='airflow' AIRFLOW_CTX_DAG_ID='Web_Scraping' AIRFLOW_CTX_TASK_ID='wait_1' AIRFLOW_CTX_EXECUTION_DATE='2023-01-01T00:00:00+00:00' AIRFLOW_CTX_TRY_NUMBER='1' AIRFLOW_CTX_DAG_RUN_ID='scheduled__2023-01-01T00:00:00+00:00'
[2025-04-21T01:31:26.318-0300] {taskinstance.py:731} INFO - ::endgroup::
[2025-04-21T01:31:58.584-0300] {local_task_job_runner.py:346} WARNING - State of this instance has been externally set to None. Terminating instance.
[2025-04-21T01:31:58.585-0300] {local_task_job_runner.py:245} INFO - ::endgroup::
[2025-04-21T01:31:58.589-0300] {process_utils.py:132} INFO - Sending 15 to group 7491. PIDs of all processes in the group: [7491]
[2025-04-21T01:31:58.589-0300] {process_utils.py:87} INFO - Sending the signal 15 to group 7491
[2025-04-21T01:31:58.590-0300] {taskinstance.py:3093} ERROR - Received SIGTERM. Terminating subprocesses.
[2025-04-21T01:31:58.600-0300] {taskinstance.py:3311} ERROR - Task failed with exception
Traceback (most recent call last):
  File "/home/lenovo/miniconda3/envs/worker/lib/python3.12/site-packages/airflow/models/taskinstance.py", line 767, in _execute_task
    result = _execute_callable(context=context, **execute_callable_kwargs)
             ^^^^^^^^^^^^^^^^^^^^^^^^^^^^^^^^^^^^^^^^^^^^^^^^^^^^^^^^^^^^^
  File "/home/lenovo/miniconda3/envs/worker/lib/python3.12/site-packages/airflow/models/taskinstance.py", line 733, in _execute_callable
    return ExecutionCallableRunner(
           ^^^^^^^^^^^^^^^^^^^^^^^^
  File "/home/lenovo/miniconda3/envs/worker/lib/python3.12/site-packages/airflow/utils/operator_helpers.py", line 252, in run
    return self.func(*args, **kwargs)
           ^^^^^^^^^^^^^^^^^^^^^^^^^^
  File "/home/lenovo/miniconda3/envs/worker/lib/python3.12/site-packages/airflow/models/baseoperator.py", line 422, in wrapper
    return func(self, *args, **kwargs)
           ^^^^^^^^^^^^^^^^^^^^^^^^^^^
  File "/home/lenovo/miniconda3/envs/worker/lib/python3.12/site-packages/airflow/operators/python.py", line 238, in execute
    return_value = self.execute_callable()
                   ^^^^^^^^^^^^^^^^^^^^^^^
  File "/home/lenovo/miniconda3/envs/worker/lib/python3.12/site-packages/airflow/operators/python.py", line 256, in execute_callable
    return runner.run(*self.op_args, **self.op_kwargs)
           ^^^^^^^^^^^^^^^^^^^^^^^^^^^^^^^^^^^^^^^^^^^
  File "/home/lenovo/miniconda3/envs/worker/lib/python3.12/site-packages/airflow/utils/operator_helpers.py", line 252, in run
    return self.func(*args, **kwargs)
           ^^^^^^^^^^^^^^^^^^^^^^^^^^
  File "/home/lenovo/airflow/dags/Ifood_case.py", line 55, in espera
    time.sleep(60)
  File "/home/lenovo/miniconda3/envs/worker/lib/python3.12/site-packages/airflow/models/taskinstance.py", line 3095, in signal_handler
    raise AirflowTaskTerminated("Task received SIGTERM signal")
airflow.exceptions.AirflowTaskTerminated: Task received SIGTERM signal
[2025-04-21T01:31:58.605-0300] {taskinstance.py:1225} INFO - Marking task as UP_FOR_RETRY. dag_id=Web_Scraping, task_id=wait_1, run_id=scheduled__2023-01-01T00:00:00+00:00, execution_date=20230101T000000, start_date=20250421T043126, end_date=20250421T043158
[2025-04-21T01:31:58.619-0300] {taskinstance.py:340} INFO - ::group::Post task execution logs
[2025-04-21T01:31:58.620-0300] {standard_task_runner.py:124} ERROR - Failed to execute job 12 for task wait_1 ((sqlite3.IntegrityError) FOREIGN KEY constraint failed
[SQL: INSERT INTO task_fail (task_id, dag_id, run_id, map_index, start_date, end_date, duration) VALUES (?, ?, ?, ?, ?, ?, ?)]
[parameters: ('wait_1', 'Web_Scraping', 'scheduled__2023-01-01T00:00:00+00:00', -1, '2025-04-21 04:31:26.135817', '2025-04-21 04:31:58.604764', 32)]
(Background on this error at: https://sqlalche.me/e/14/gkpj); 7491)
Traceback (most recent call last):
  File "/home/lenovo/miniconda3/envs/worker/lib/python3.12/site-packages/airflow/models/taskinstance.py", line 273, in _run_raw_task
    TaskInstance._execute_task_with_callbacks(
  File "/home/lenovo/miniconda3/envs/worker/lib/python3.12/site-packages/airflow/models/taskinstance.py", line 3159, in _execute_task_with_callbacks
    result = self._execute_task(context, task_orig)
             ^^^^^^^^^^^^^^^^^^^^^^^^^^^^^^^^^^^^^^
  File "/home/lenovo/miniconda3/envs/worker/lib/python3.12/site-packages/airflow/models/taskinstance.py", line 3183, in _execute_task
    return _execute_task(self, context, task_orig)
           ^^^^^^^^^^^^^^^^^^^^^^^^^^^^^^^^^^^^^^^
  File "/home/lenovo/miniconda3/envs/worker/lib/python3.12/site-packages/airflow/models/taskinstance.py", line 767, in _execute_task
    result = _execute_callable(context=context, **execute_callable_kwargs)
             ^^^^^^^^^^^^^^^^^^^^^^^^^^^^^^^^^^^^^^^^^^^^^^^^^^^^^^^^^^^^^
  File "/home/lenovo/miniconda3/envs/worker/lib/python3.12/site-packages/airflow/models/taskinstance.py", line 733, in _execute_callable
    return ExecutionCallableRunner(
           ^^^^^^^^^^^^^^^^^^^^^^^^
  File "/home/lenovo/miniconda3/envs/worker/lib/python3.12/site-packages/airflow/utils/operator_helpers.py", line 252, in run
    return self.func(*args, **kwargs)
           ^^^^^^^^^^^^^^^^^^^^^^^^^^
  File "/home/lenovo/miniconda3/envs/worker/lib/python3.12/site-packages/airflow/models/baseoperator.py", line 422, in wrapper
    return func(self, *args, **kwargs)
           ^^^^^^^^^^^^^^^^^^^^^^^^^^^
  File "/home/lenovo/miniconda3/envs/worker/lib/python3.12/site-packages/airflow/operators/python.py", line 238, in execute
    return_value = self.execute_callable()
                   ^^^^^^^^^^^^^^^^^^^^^^^
  File "/home/lenovo/miniconda3/envs/worker/lib/python3.12/site-packages/airflow/operators/python.py", line 256, in execute_callable
    return runner.run(*self.op_args, **self.op_kwargs)
           ^^^^^^^^^^^^^^^^^^^^^^^^^^^^^^^^^^^^^^^^^^^
  File "/home/lenovo/miniconda3/envs/worker/lib/python3.12/site-packages/airflow/utils/operator_helpers.py", line 252, in run
    return self.func(*args, **kwargs)
           ^^^^^^^^^^^^^^^^^^^^^^^^^^
  File "/home/lenovo/airflow/dags/Ifood_case.py", line 55, in espera
    time.sleep(60)
  File "/home/lenovo/miniconda3/envs/worker/lib/python3.12/site-packages/airflow/models/taskinstance.py", line 3095, in signal_handler
    raise AirflowTaskTerminated("Task received SIGTERM signal")
airflow.exceptions.AirflowTaskTerminated: Task received SIGTERM signal

During handling of the above exception, another exception occurred:

Traceback (most recent call last):
  File "/home/lenovo/miniconda3/envs/worker/lib/python3.12/site-packages/sqlalchemy/engine/base.py", line 1910, in _execute_context
    self.dialect.do_execute(
  File "/home/lenovo/miniconda3/envs/worker/lib/python3.12/site-packages/sqlalchemy/engine/default.py", line 736, in do_execute
    cursor.execute(statement, parameters)
sqlite3.IntegrityError: FOREIGN KEY constraint failed

The above exception was the direct cause of the following exception:

Traceback (most recent call last):
  File "/home/lenovo/miniconda3/envs/worker/lib/python3.12/site-packages/airflow/task/task_runner/standard_task_runner.py", line 117, in _start_by_fork
    ret = args.func(args, dag=self.dag)
          ^^^^^^^^^^^^^^^^^^^^^^^^^^^^^
  File "/home/lenovo/miniconda3/envs/worker/lib/python3.12/site-packages/airflow/cli/cli_config.py", line 49, in command
    return func(*args, **kwargs)
           ^^^^^^^^^^^^^^^^^^^^^
  File "/home/lenovo/miniconda3/envs/worker/lib/python3.12/site-packages/airflow/utils/cli.py", line 116, in wrapper
    return f(*args, **kwargs)
           ^^^^^^^^^^^^^^^^^^
  File "/home/lenovo/miniconda3/envs/worker/lib/python3.12/site-packages/airflow/cli/commands/task_command.py", line 483, in task_run
    task_return_code = _run_task_by_selected_method(args, _dag, ti)
                       ^^^^^^^^^^^^^^^^^^^^^^^^^^^^^^^^^^^^^^^^^^^^
  File "/home/lenovo/miniconda3/envs/worker/lib/python3.12/site-packages/airflow/cli/commands/task_command.py", line 256, in _run_task_by_selected_method
    return _run_raw_task(args, ti)
           ^^^^^^^^^^^^^^^^^^^^^^^
  File "/home/lenovo/miniconda3/envs/worker/lib/python3.12/site-packages/airflow/cli/commands/task_command.py", line 341, in _run_raw_task
    return ti._run_raw_task(
           ^^^^^^^^^^^^^^^^^
  File "/home/lenovo/miniconda3/envs/worker/lib/python3.12/site-packages/airflow/utils/session.py", line 97, in wrapper
    return func(*args, session=session, **kwargs)
           ^^^^^^^^^^^^^^^^^^^^^^^^^^^^^^^^^^^^^^
  File "/home/lenovo/miniconda3/envs/worker/lib/python3.12/site-packages/airflow/models/taskinstance.py", line 3005, in _run_raw_task
    return _run_raw_task(
           ^^^^^^^^^^^^^^
  File "/home/lenovo/miniconda3/envs/worker/lib/python3.12/site-packages/airflow/models/taskinstance.py", line 327, in _run_raw_task
    ti.handle_failure(e, test_mode, context, session=session)
  File "/home/lenovo/miniconda3/envs/worker/lib/python3.12/site-packages/airflow/utils/session.py", line 94, in wrapper
    return func(*args, **kwargs)
           ^^^^^^^^^^^^^^^^^^^^^
  File "/home/lenovo/miniconda3/envs/worker/lib/python3.12/site-packages/airflow/models/taskinstance.py", line 3428, in handle_failure
    _handle_failure(
  File "/home/lenovo/miniconda3/envs/worker/lib/python3.12/site-packages/airflow/utils/session.py", line 94, in wrapper
    return func(*args, **kwargs)
           ^^^^^^^^^^^^^^^^^^^^^
  File "/home/lenovo/miniconda3/envs/worker/lib/python3.12/site-packages/airflow/api_internal/internal_api_call.py", line 166, in wrapper
    return func(*args, **kwargs)
           ^^^^^^^^^^^^^^^^^^^^^
  File "/home/lenovo/miniconda3/envs/worker/lib/python3.12/site-packages/airflow/models/taskinstance.py", line 1243, in _handle_failure
    TaskInstance.save_to_db(failure_context["ti"], session)
  File "/home/lenovo/miniconda3/envs/worker/lib/python3.12/site-packages/airflow/api_internal/internal_api_call.py", line 166, in wrapper
    return func(*args, **kwargs)
           ^^^^^^^^^^^^^^^^^^^^^
  File "/home/lenovo/miniconda3/envs/worker/lib/python3.12/site-packages/airflow/utils/session.py", line 94, in wrapper
    return func(*args, **kwargs)
           ^^^^^^^^^^^^^^^^^^^^^
  File "/home/lenovo/miniconda3/envs/worker/lib/python3.12/site-packages/airflow/models/taskinstance.py", line 3400, in save_to_db
    session.flush()
  File "/home/lenovo/miniconda3/envs/worker/lib/python3.12/site-packages/sqlalchemy/orm/session.py", line 3449, in flush
    self._flush(objects)
  File "/home/lenovo/miniconda3/envs/worker/lib/python3.12/site-packages/sqlalchemy/orm/session.py", line 3588, in _flush
    with util.safe_reraise():
         ^^^^^^^^^^^^^^^^^^^
  File "/home/lenovo/miniconda3/envs/worker/lib/python3.12/site-packages/sqlalchemy/util/langhelpers.py", line 70, in __exit__
    compat.raise_(
  File "/home/lenovo/miniconda3/envs/worker/lib/python3.12/site-packages/sqlalchemy/util/compat.py", line 211, in raise_
    raise exception
  File "/home/lenovo/miniconda3/envs/worker/lib/python3.12/site-packages/sqlalchemy/orm/session.py", line 3549, in _flush
    flush_context.execute()
  File "/home/lenovo/miniconda3/envs/worker/lib/python3.12/site-packages/sqlalchemy/orm/unitofwork.py", line 456, in execute
    rec.execute(self)
  File "/home/lenovo/miniconda3/envs/worker/lib/python3.12/site-packages/sqlalchemy/orm/unitofwork.py", line 630, in execute
    util.preloaded.orm_persistence.save_obj(
  File "/home/lenovo/miniconda3/envs/worker/lib/python3.12/site-packages/sqlalchemy/orm/persistence.py", line 245, in save_obj
    _emit_insert_statements(
  File "/home/lenovo/miniconda3/envs/worker/lib/python3.12/site-packages/sqlalchemy/orm/persistence.py", line 1238, in _emit_insert_statements
    result = connection._execute_20(
             ^^^^^^^^^^^^^^^^^^^^^^^
  File "/home/lenovo/miniconda3/envs/worker/lib/python3.12/site-packages/sqlalchemy/engine/base.py", line 1710, in _execute_20
    return meth(self, args_10style, kwargs_10style, execution_options)
           ^^^^^^^^^^^^^^^^^^^^^^^^^^^^^^^^^^^^^^^^^^^^^^^^^^^^^^^^^^^
  File "/home/lenovo/miniconda3/envs/worker/lib/python3.12/site-packages/sqlalchemy/sql/elements.py", line 334, in _execute_on_connection
    return connection._execute_clauseelement(
           ^^^^^^^^^^^^^^^^^^^^^^^^^^^^^^^^^^
  File "/home/lenovo/miniconda3/envs/worker/lib/python3.12/site-packages/sqlalchemy/engine/base.py", line 1577, in _execute_clauseelement
    ret = self._execute_context(
          ^^^^^^^^^^^^^^^^^^^^^^
  File "/home/lenovo/miniconda3/envs/worker/lib/python3.12/site-packages/sqlalchemy/engine/base.py", line 1953, in _execute_context
    self._handle_dbapi_exception(
  File "/home/lenovo/miniconda3/envs/worker/lib/python3.12/site-packages/sqlalchemy/engine/base.py", line 2134, in _handle_dbapi_exception
    util.raise_(
  File "/home/lenovo/miniconda3/envs/worker/lib/python3.12/site-packages/sqlalchemy/util/compat.py", line 211, in raise_
    raise exception
  File "/home/lenovo/miniconda3/envs/worker/lib/python3.12/site-packages/sqlalchemy/engine/base.py", line 1910, in _execute_context
    self.dialect.do_execute(
  File "/home/lenovo/miniconda3/envs/worker/lib/python3.12/site-packages/sqlalchemy/engine/default.py", line 736, in do_execute
    cursor.execute(statement, parameters)
sqlalchemy.exc.IntegrityError: (sqlite3.IntegrityError) FOREIGN KEY constraint failed
[SQL: INSERT INTO task_fail (task_id, dag_id, run_id, map_index, start_date, end_date, duration) VALUES (?, ?, ?, ?, ?, ?, ?)]
[parameters: ('wait_1', 'Web_Scraping', 'scheduled__2023-01-01T00:00:00+00:00', -1, '2025-04-21 04:31:26.135817', '2025-04-21 04:31:58.604764', 32)]
(Background on this error at: https://sqlalche.me/e/14/gkpj)
[2025-04-21T01:31:58.682-0300] {process_utils.py:80} INFO - Process psutil.Process(pid=7491, status='terminated', exitcode=1, started='01:31:25') (7491) terminated with exit code 1
