[2025-04-21T01:51:16.623-0300] {local_task_job_runner.py:123} INFO - ::group::Pre task execution logs
[2025-04-21T01:51:16.654-0300] {taskinstance.py:2613} INFO - Dependencies all met for dep_context=non-requeueable deps ti=<TaskInstance: Scraping.wait_1 scheduled__2025-04-20T00:00:00+00:00 [queued]>
[2025-04-21T01:51:16.664-0300] {taskinstance.py:2613} INFO - Dependencies all met for dep_context=requeueable deps ti=<TaskInstance: Scraping.wait_1 scheduled__2025-04-20T00:00:00+00:00 [queued]>
[2025-04-21T01:51:16.664-0300] {taskinstance.py:2866} INFO - Starting attempt 1 of 2
[2025-04-21T01:51:16.690-0300] {taskinstance.py:2889} INFO - Executing <Task(PythonOperator): wait_1> on 2025-04-20 00:00:00+00:00
[2025-04-21T01:51:16.695-0300] {standard_task_runner.py:72} INFO - Started process 10704 to run task
[2025-04-21T01:51:16.699-0300] {standard_task_runner.py:104} INFO - Running: ['airflow', 'tasks', 'run', 'Scraping', 'wait_1', 'scheduled__2025-04-20T00:00:00+00:00', '--job-id', '20', '--raw', '--subdir', 'DAGS_FOLDER/Scraping.py', '--cfg-path', '/tmp/tmpnjt89t9s']
[2025-04-21T01:51:16.700-0300] {standard_task_runner.py:105} INFO - Job 20: Subtask wait_1
[2025-04-21T01:51:16.751-0300] {task_command.py:467} INFO - Running <TaskInstance: Scraping.wait_1 scheduled__2025-04-20T00:00:00+00:00 [running]> on host DESKTOP-1GIT60U.
[2025-04-21T01:51:16.865-0300] {taskinstance.py:3132} INFO - Exporting env vars: AIRFLOW_CTX_DAG_EMAIL='airflow@example.com' AIRFLOW_CTX_DAG_OWNER='airflow' AIRFLOW_CTX_DAG_ID='Scraping' AIRFLOW_CTX_TASK_ID='wait_1' AIRFLOW_CTX_EXECUTION_DATE='2025-04-20T00:00:00+00:00' AIRFLOW_CTX_TRY_NUMBER='1' AIRFLOW_CTX_DAG_RUN_ID='scheduled__2025-04-20T00:00:00+00:00'
[2025-04-21T01:51:16.867-0300] {taskinstance.py:731} INFO - ::endgroup::
[2025-04-21T01:51:34.196-0300] {local_task_job_runner.py:346} WARNING - State of this instance has been externally set to None. Terminating instance.
[2025-04-21T01:51:34.197-0300] {local_task_job_runner.py:245} INFO - ::endgroup::
[2025-04-21T01:51:34.200-0300] {process_utils.py:132} INFO - Sending 15 to group 10704. PIDs of all processes in the group: [10704]
[2025-04-21T01:51:34.201-0300] {process_utils.py:87} INFO - Sending the signal 15 to group 10704
[2025-04-21T01:51:34.201-0300] {taskinstance.py:3093} ERROR - Received SIGTERM. Terminating subprocesses.
[2025-04-21T01:51:34.208-0300] {taskinstance.py:3311} ERROR - Task failed with exception
Traceback (most recent call last):
  File "/home/lenovo/miniconda3/envs/worker/lib/python3.12/site-packages/airflow/models/taskinstance.py", line 767, in _execute_task
    result = _execute_callable(context=context, **execute_callable_kwargs)
             ^^^^^^^^^^^^^^^^^^^^^^^^^^^^^^^^^^^^^^^^^^^^^^^^^^^^^^^^^^^^^
  File "/home/lenovo/miniconda3/envs/worker/lib/python3.12/site-packages/airflow/models/taskinstance.py", line 733, in _execute_callable
    return ExecutionCallableRunner(
           ^^^^^^^^^^^^^^^^^^^^^^^^
  File "/home/lenovo/miniconda3/envs/worker/lib/python3.12/site-packages/airflow/utils/operator_helpers.py", line 252, in run
    return self.func(*args, **kwargs)
           ^^^^^^^^^^^^^^^^^^^^^^^^^^
  File "/home/lenovo/miniconda3/envs/worker/lib/python3.12/site-packages/airflow/models/baseoperator.py", line 422, in wrapper
    return func(self, *args, **kwargs)
           ^^^^^^^^^^^^^^^^^^^^^^^^^^^
  File "/home/lenovo/miniconda3/envs/worker/lib/python3.12/site-packages/airflow/operators/python.py", line 238, in execute
    return_value = self.execute_callable()
                   ^^^^^^^^^^^^^^^^^^^^^^^
  File "/home/lenovo/miniconda3/envs/worker/lib/python3.12/site-packages/airflow/operators/python.py", line 256, in execute_callable
    return runner.run(*self.op_args, **self.op_kwargs)
           ^^^^^^^^^^^^^^^^^^^^^^^^^^^^^^^^^^^^^^^^^^^
  File "/home/lenovo/miniconda3/envs/worker/lib/python3.12/site-packages/airflow/utils/operator_helpers.py", line 252, in run
    return self.func(*args, **kwargs)
           ^^^^^^^^^^^^^^^^^^^^^^^^^^
  File "/home/lenovo/airflow/dags/Scraping.py", line 59, in espera
    time.sleep(60)
  File "/home/lenovo/miniconda3/envs/worker/lib/python3.12/site-packages/airflow/models/taskinstance.py", line 3095, in signal_handler
    raise AirflowTaskTerminated("Task received SIGTERM signal")
airflow.exceptions.AirflowTaskTerminated: Task received SIGTERM signal
[2025-04-21T01:51:34.213-0300] {taskinstance.py:1225} INFO - Marking task as UP_FOR_RETRY. dag_id=Scraping, task_id=wait_1, run_id=scheduled__2025-04-20T00:00:00+00:00, execution_date=20250420T000000, start_date=20250421T045116, end_date=20250421T045134
[2025-04-21T01:51:34.225-0300] {taskinstance.py:340} INFO - ::group::Post task execution logs
[2025-04-21T01:51:34.226-0300] {standard_task_runner.py:124} ERROR - Failed to execute job 20 for task wait_1 ((sqlite3.IntegrityError) FOREIGN KEY constraint failed
[SQL: INSERT INTO task_fail (task_id, dag_id, run_id, map_index, start_date, end_date, duration) VALUES (?, ?, ?, ?, ?, ?, ?)]
[parameters: ('wait_1', 'Scraping', 'scheduled__2025-04-20T00:00:00+00:00', -1, '2025-04-21 04:51:16.654733', '2025-04-21 04:51:34.213039', 17)]
(Background on this error at: https://sqlalche.me/e/14/gkpj); 10704)
Traceback (most recent call last):
  File "/home/lenovo/miniconda3/envs/worker/lib/python3.12/site-packages/airflow/models/taskinstance.py", line 273, in _run_raw_task
    TaskInstance._execute_task_with_callbacks(
  File "/home/lenovo/miniconda3/envs/worker/lib/python3.12/site-packages/airflow/models/taskinstance.py", line 3159, in _execute_task_with_callbacks
    result = self._execute_task(context, task_orig)
             ^^^^^^^^^^^^^^^^^^^^^^^^^^^^^^^^^^^^^^
  File "/home/lenovo/miniconda3/envs/worker/lib/python3.12/site-packages/airflow/models/taskinstance.py", line 3183, in _execute_task
    return _execute_task(self, context, task_orig)
           ^^^^^^^^^^^^^^^^^^^^^^^^^^^^^^^^^^^^^^^
  File "/home/lenovo/miniconda3/envs/worker/lib/python3.12/site-packages/airflow/models/taskinstance.py", line 767, in _execute_task
    result = _execute_callable(context=context, **execute_callable_kwargs)
             ^^^^^^^^^^^^^^^^^^^^^^^^^^^^^^^^^^^^^^^^^^^^^^^^^^^^^^^^^^^^^
  File "/home/lenovo/miniconda3/envs/worker/lib/python3.12/site-packages/airflow/models/taskinstance.py", line 733, in _execute_callable
    return ExecutionCallableRunner(
           ^^^^^^^^^^^^^^^^^^^^^^^^
  File "/home/lenovo/miniconda3/envs/worker/lib/python3.12/site-packages/airflow/utils/operator_helpers.py", line 252, in run
    return self.func(*args, **kwargs)
           ^^^^^^^^^^^^^^^^^^^^^^^^^^
  File "/home/lenovo/miniconda3/envs/worker/lib/python3.12/site-packages/airflow/models/baseoperator.py", line 422, in wrapper
    return func(self, *args, **kwargs)
           ^^^^^^^^^^^^^^^^^^^^^^^^^^^
  File "/home/lenovo/miniconda3/envs/worker/lib/python3.12/site-packages/airflow/operators/python.py", line 238, in execute
    return_value = self.execute_callable()
                   ^^^^^^^^^^^^^^^^^^^^^^^
  File "/home/lenovo/miniconda3/envs/worker/lib/python3.12/site-packages/airflow/operators/python.py", line 256, in execute_callable
    return runner.run(*self.op_args, **self.op_kwargs)
           ^^^^^^^^^^^^^^^^^^^^^^^^^^^^^^^^^^^^^^^^^^^
  File "/home/lenovo/miniconda3/envs/worker/lib/python3.12/site-packages/airflow/utils/operator_helpers.py", line 252, in run
    return self.func(*args, **kwargs)
           ^^^^^^^^^^^^^^^^^^^^^^^^^^
  File "/home/lenovo/airflow/dags/Scraping.py", line 59, in espera
    time.sleep(60)
  File "/home/lenovo/miniconda3/envs/worker/lib/python3.12/site-packages/airflow/models/taskinstance.py", line 3095, in signal_handler
    raise AirflowTaskTerminated("Task received SIGTERM signal")
airflow.exceptions.AirflowTaskTerminated: Task received SIGTERM signal

During handling of the above exception, another exception occurred:

Traceback (most recent call last):
  File "/home/lenovo/miniconda3/envs/worker/lib/python3.12/site-packages/sqlalchemy/engine/base.py", line 1910, in _execute_context
    self.dialect.do_execute(
  File "/home/lenovo/miniconda3/envs/worker/lib/python3.12/site-packages/sqlalchemy/engine/default.py", line 736, in do_execute
    cursor.execute(statement, parameters)
sqlite3.IntegrityError: FOREIGN KEY constraint failed

The above exception was the direct cause of the following exception:

Traceback (most recent call last):
  File "/home/lenovo/miniconda3/envs/worker/lib/python3.12/site-packages/airflow/task/task_runner/standard_task_runner.py", line 117, in _start_by_fork
    ret = args.func(args, dag=self.dag)
          ^^^^^^^^^^^^^^^^^^^^^^^^^^^^^
  File "/home/lenovo/miniconda3/envs/worker/lib/python3.12/site-packages/airflow/cli/cli_config.py", line 49, in command
    return func(*args, **kwargs)
           ^^^^^^^^^^^^^^^^^^^^^
  File "/home/lenovo/miniconda3/envs/worker/lib/python3.12/site-packages/airflow/utils/cli.py", line 116, in wrapper
    return f(*args, **kwargs)
           ^^^^^^^^^^^^^^^^^^
  File "/home/lenovo/miniconda3/envs/worker/lib/python3.12/site-packages/airflow/cli/commands/task_command.py", line 483, in task_run
    task_return_code = _run_task_by_selected_method(args, _dag, ti)
                       ^^^^^^^^^^^^^^^^^^^^^^^^^^^^^^^^^^^^^^^^^^^^
  File "/home/lenovo/miniconda3/envs/worker/lib/python3.12/site-packages/airflow/cli/commands/task_command.py", line 256, in _run_task_by_selected_method
    return _run_raw_task(args, ti)
           ^^^^^^^^^^^^^^^^^^^^^^^
  File "/home/lenovo/miniconda3/envs/worker/lib/python3.12/site-packages/airflow/cli/commands/task_command.py", line 341, in _run_raw_task
    return ti._run_raw_task(
           ^^^^^^^^^^^^^^^^^
  File "/home/lenovo/miniconda3/envs/worker/lib/python3.12/site-packages/airflow/utils/session.py", line 97, in wrapper
    return func(*args, session=session, **kwargs)
           ^^^^^^^^^^^^^^^^^^^^^^^^^^^^^^^^^^^^^^
  File "/home/lenovo/miniconda3/envs/worker/lib/python3.12/site-packages/airflow/models/taskinstance.py", line 3005, in _run_raw_task
    return _run_raw_task(
           ^^^^^^^^^^^^^^
  File "/home/lenovo/miniconda3/envs/worker/lib/python3.12/site-packages/airflow/models/taskinstance.py", line 327, in _run_raw_task
    ti.handle_failure(e, test_mode, context, session=session)
  File "/home/lenovo/miniconda3/envs/worker/lib/python3.12/site-packages/airflow/utils/session.py", line 94, in wrapper
    return func(*args, **kwargs)
           ^^^^^^^^^^^^^^^^^^^^^
  File "/home/lenovo/miniconda3/envs/worker/lib/python3.12/site-packages/airflow/models/taskinstance.py", line 3428, in handle_failure
    _handle_failure(
  File "/home/lenovo/miniconda3/envs/worker/lib/python3.12/site-packages/airflow/utils/session.py", line 94, in wrapper
    return func(*args, **kwargs)
           ^^^^^^^^^^^^^^^^^^^^^
  File "/home/lenovo/miniconda3/envs/worker/lib/python3.12/site-packages/airflow/api_internal/internal_api_call.py", line 166, in wrapper
    return func(*args, **kwargs)
           ^^^^^^^^^^^^^^^^^^^^^
  File "/home/lenovo/miniconda3/envs/worker/lib/python3.12/site-packages/airflow/models/taskinstance.py", line 1243, in _handle_failure
    TaskInstance.save_to_db(failure_context["ti"], session)
  File "/home/lenovo/miniconda3/envs/worker/lib/python3.12/site-packages/airflow/api_internal/internal_api_call.py", line 166, in wrapper
    return func(*args, **kwargs)
           ^^^^^^^^^^^^^^^^^^^^^
  File "/home/lenovo/miniconda3/envs/worker/lib/python3.12/site-packages/airflow/utils/session.py", line 94, in wrapper
    return func(*args, **kwargs)
           ^^^^^^^^^^^^^^^^^^^^^
  File "/home/lenovo/miniconda3/envs/worker/lib/python3.12/site-packages/airflow/models/taskinstance.py", line 3400, in save_to_db
    session.flush()
  File "/home/lenovo/miniconda3/envs/worker/lib/python3.12/site-packages/sqlalchemy/orm/session.py", line 3449, in flush
    self._flush(objects)
  File "/home/lenovo/miniconda3/envs/worker/lib/python3.12/site-packages/sqlalchemy/orm/session.py", line 3588, in _flush
    with util.safe_reraise():
         ^^^^^^^^^^^^^^^^^^^
  File "/home/lenovo/miniconda3/envs/worker/lib/python3.12/site-packages/sqlalchemy/util/langhelpers.py", line 70, in __exit__
    compat.raise_(
  File "/home/lenovo/miniconda3/envs/worker/lib/python3.12/site-packages/sqlalchemy/util/compat.py", line 211, in raise_
    raise exception
  File "/home/lenovo/miniconda3/envs/worker/lib/python3.12/site-packages/sqlalchemy/orm/session.py", line 3549, in _flush
    flush_context.execute()
  File "/home/lenovo/miniconda3/envs/worker/lib/python3.12/site-packages/sqlalchemy/orm/unitofwork.py", line 456, in execute
    rec.execute(self)
  File "/home/lenovo/miniconda3/envs/worker/lib/python3.12/site-packages/sqlalchemy/orm/unitofwork.py", line 630, in execute
    util.preloaded.orm_persistence.save_obj(
  File "/home/lenovo/miniconda3/envs/worker/lib/python3.12/site-packages/sqlalchemy/orm/persistence.py", line 245, in save_obj
    _emit_insert_statements(
  File "/home/lenovo/miniconda3/envs/worker/lib/python3.12/site-packages/sqlalchemy/orm/persistence.py", line 1238, in _emit_insert_statements
    result = connection._execute_20(
             ^^^^^^^^^^^^^^^^^^^^^^^
  File "/home/lenovo/miniconda3/envs/worker/lib/python3.12/site-packages/sqlalchemy/engine/base.py", line 1710, in _execute_20
    return meth(self, args_10style, kwargs_10style, execution_options)
           ^^^^^^^^^^^^^^^^^^^^^^^^^^^^^^^^^^^^^^^^^^^^^^^^^^^^^^^^^^^
  File "/home/lenovo/miniconda3/envs/worker/lib/python3.12/site-packages/sqlalchemy/sql/elements.py", line 334, in _execute_on_connection
    return connection._execute_clauseelement(
           ^^^^^^^^^^^^^^^^^^^^^^^^^^^^^^^^^^
  File "/home/lenovo/miniconda3/envs/worker/lib/python3.12/site-packages/sqlalchemy/engine/base.py", line 1577, in _execute_clauseelement
    ret = self._execute_context(
          ^^^^^^^^^^^^^^^^^^^^^^
  File "/home/lenovo/miniconda3/envs/worker/lib/python3.12/site-packages/sqlalchemy/engine/base.py", line 1953, in _execute_context
    self._handle_dbapi_exception(
  File "/home/lenovo/miniconda3/envs/worker/lib/python3.12/site-packages/sqlalchemy/engine/base.py", line 2134, in _handle_dbapi_exception
    util.raise_(
  File "/home/lenovo/miniconda3/envs/worker/lib/python3.12/site-packages/sqlalchemy/util/compat.py", line 211, in raise_
    raise exception
  File "/home/lenovo/miniconda3/envs/worker/lib/python3.12/site-packages/sqlalchemy/engine/base.py", line 1910, in _execute_context
    self.dialect.do_execute(
  File "/home/lenovo/miniconda3/envs/worker/lib/python3.12/site-packages/sqlalchemy/engine/default.py", line 736, in do_execute
    cursor.execute(statement, parameters)
sqlalchemy.exc.IntegrityError: (sqlite3.IntegrityError) FOREIGN KEY constraint failed
[SQL: INSERT INTO task_fail (task_id, dag_id, run_id, map_index, start_date, end_date, duration) VALUES (?, ?, ?, ?, ?, ?, ?)]
[parameters: ('wait_1', 'Scraping', 'scheduled__2025-04-20T00:00:00+00:00', -1, '2025-04-21 04:51:16.654733', '2025-04-21 04:51:34.213039', 17)]
(Background on this error at: https://sqlalche.me/e/14/gkpj)
[2025-04-21T01:51:34.253-0300] {process_utils.py:80} INFO - Process psutil.Process(pid=10704, status='terminated', exitcode=1, started='01:51:16') (10704) terminated with exit code 1
[2025-04-21T03:03:07.086-0300] {local_task_job_runner.py:123} INFO - ::group::Pre task execution logs
[2025-04-21T03:03:07.116-0300] {taskinstance.py:2613} INFO - Dependencies all met for dep_context=non-requeueable deps ti=<TaskInstance: Scraping.wait_1 scheduled__2025-04-20T00:00:00+00:00 [queued]>
[2025-04-21T03:03:07.129-0300] {taskinstance.py:2613} INFO - Dependencies all met for dep_context=requeueable deps ti=<TaskInstance: Scraping.wait_1 scheduled__2025-04-20T00:00:00+00:00 [queued]>
[2025-04-21T03:03:07.130-0300] {taskinstance.py:2866} INFO - Starting attempt 1 of 2
[2025-04-21T03:03:07.160-0300] {taskinstance.py:2889} INFO - Executing <Task(PythonOperator): wait_1> on 2025-04-20 00:00:00+00:00
[2025-04-21T03:03:07.165-0300] {standard_task_runner.py:72} INFO - Started process 30004 to run task
[2025-04-21T03:03:07.169-0300] {standard_task_runner.py:104} INFO - Running: ['airflow', 'tasks', 'run', 'Scraping', 'wait_1', 'scheduled__2025-04-20T00:00:00+00:00', '--job-id', '52', '--raw', '--subdir', 'DAGS_FOLDER/Scraping.py', '--cfg-path', '/tmp/tmp0veq58nv']
[2025-04-21T03:03:07.170-0300] {standard_task_runner.py:105} INFO - Job 52: Subtask wait_1
[2025-04-21T03:03:07.217-0300] {task_command.py:467} INFO - Running <TaskInstance: Scraping.wait_1 scheduled__2025-04-20T00:00:00+00:00 [running]> on host DESKTOP-1GIT60U.
[2025-04-21T03:03:07.312-0300] {taskinstance.py:3132} INFO - Exporting env vars: AIRFLOW_CTX_DAG_EMAIL='airflow@example.com' AIRFLOW_CTX_DAG_OWNER='airflow' AIRFLOW_CTX_DAG_ID='Scraping' AIRFLOW_CTX_TASK_ID='wait_1' AIRFLOW_CTX_EXECUTION_DATE='2025-04-20T00:00:00+00:00' AIRFLOW_CTX_TRY_NUMBER='1' AIRFLOW_CTX_DAG_RUN_ID='scheduled__2025-04-20T00:00:00+00:00'
[2025-04-21T03:03:07.313-0300] {taskinstance.py:731} INFO - ::endgroup::
[2025-04-21T03:03:19.270-0300] {local_task_job_runner.py:346} WARNING - State of this instance has been externally set to None. Terminating instance.
[2025-04-21T03:03:19.272-0300] {local_task_job_runner.py:245} INFO - ::endgroup::
[2025-04-21T03:03:19.276-0300] {process_utils.py:132} INFO - Sending 15 to group 30004. PIDs of all processes in the group: [30004]
[2025-04-21T03:03:19.277-0300] {process_utils.py:87} INFO - Sending the signal 15 to group 30004
[2025-04-21T03:03:19.277-0300] {taskinstance.py:3093} ERROR - Received SIGTERM. Terminating subprocesses.
[2025-04-21T03:03:19.284-0300] {taskinstance.py:3311} ERROR - Task failed with exception
Traceback (most recent call last):
  File "/home/lenovo/miniconda3/envs/worker/lib/python3.12/site-packages/airflow/models/taskinstance.py", line 767, in _execute_task
    result = _execute_callable(context=context, **execute_callable_kwargs)
             ^^^^^^^^^^^^^^^^^^^^^^^^^^^^^^^^^^^^^^^^^^^^^^^^^^^^^^^^^^^^^
  File "/home/lenovo/miniconda3/envs/worker/lib/python3.12/site-packages/airflow/models/taskinstance.py", line 733, in _execute_callable
    return ExecutionCallableRunner(
           ^^^^^^^^^^^^^^^^^^^^^^^^
  File "/home/lenovo/miniconda3/envs/worker/lib/python3.12/site-packages/airflow/utils/operator_helpers.py", line 252, in run
    return self.func(*args, **kwargs)
           ^^^^^^^^^^^^^^^^^^^^^^^^^^
  File "/home/lenovo/miniconda3/envs/worker/lib/python3.12/site-packages/airflow/models/baseoperator.py", line 422, in wrapper
    return func(self, *args, **kwargs)
           ^^^^^^^^^^^^^^^^^^^^^^^^^^^
  File "/home/lenovo/miniconda3/envs/worker/lib/python3.12/site-packages/airflow/operators/python.py", line 238, in execute
    return_value = self.execute_callable()
                   ^^^^^^^^^^^^^^^^^^^^^^^
  File "/home/lenovo/miniconda3/envs/worker/lib/python3.12/site-packages/airflow/operators/python.py", line 256, in execute_callable
    return runner.run(*self.op_args, **self.op_kwargs)
           ^^^^^^^^^^^^^^^^^^^^^^^^^^^^^^^^^^^^^^^^^^^
  File "/home/lenovo/miniconda3/envs/worker/lib/python3.12/site-packages/airflow/utils/operator_helpers.py", line 252, in run
    return self.func(*args, **kwargs)
           ^^^^^^^^^^^^^^^^^^^^^^^^^^
  File "/home/lenovo/airflow/dags/Scraping.py", line 59, in espera
    time.sleep(60)
  File "/home/lenovo/miniconda3/envs/worker/lib/python3.12/site-packages/airflow/models/taskinstance.py", line 3095, in signal_handler
    raise AirflowTaskTerminated("Task received SIGTERM signal")
airflow.exceptions.AirflowTaskTerminated: Task received SIGTERM signal
[2025-04-21T03:03:19.294-0300] {taskinstance.py:1225} INFO - Marking task as UP_FOR_RETRY. dag_id=Scraping, task_id=wait_1, run_id=scheduled__2025-04-20T00:00:00+00:00, execution_date=20250420T000000, start_date=20250421T060307, end_date=20250421T060319
[2025-04-21T03:03:19.308-0300] {taskinstance.py:340} INFO - ::group::Post task execution logs
[2025-04-21T03:03:19.310-0300] {standard_task_runner.py:124} ERROR - Failed to execute job 52 for task wait_1 ((sqlite3.IntegrityError) FOREIGN KEY constraint failed
[SQL: INSERT INTO task_fail (task_id, dag_id, run_id, map_index, start_date, end_date, duration) VALUES (?, ?, ?, ?, ?, ?, ?)]
[parameters: ('wait_1', 'Scraping', 'scheduled__2025-04-20T00:00:00+00:00', -1, '2025-04-21 06:03:07.117506', '2025-04-21 06:03:19.293924', 12)]
(Background on this error at: https://sqlalche.me/e/14/gkpj); 30004)
Traceback (most recent call last):
  File "/home/lenovo/miniconda3/envs/worker/lib/python3.12/site-packages/airflow/models/taskinstance.py", line 273, in _run_raw_task
    TaskInstance._execute_task_with_callbacks(
  File "/home/lenovo/miniconda3/envs/worker/lib/python3.12/site-packages/airflow/models/taskinstance.py", line 3159, in _execute_task_with_callbacks
    result = self._execute_task(context, task_orig)
             ^^^^^^^^^^^^^^^^^^^^^^^^^^^^^^^^^^^^^^
  File "/home/lenovo/miniconda3/envs/worker/lib/python3.12/site-packages/airflow/models/taskinstance.py", line 3183, in _execute_task
    return _execute_task(self, context, task_orig)
           ^^^^^^^^^^^^^^^^^^^^^^^^^^^^^^^^^^^^^^^
  File "/home/lenovo/miniconda3/envs/worker/lib/python3.12/site-packages/airflow/models/taskinstance.py", line 767, in _execute_task
    result = _execute_callable(context=context, **execute_callable_kwargs)
             ^^^^^^^^^^^^^^^^^^^^^^^^^^^^^^^^^^^^^^^^^^^^^^^^^^^^^^^^^^^^^
  File "/home/lenovo/miniconda3/envs/worker/lib/python3.12/site-packages/airflow/models/taskinstance.py", line 733, in _execute_callable
    return ExecutionCallableRunner(
           ^^^^^^^^^^^^^^^^^^^^^^^^
  File "/home/lenovo/miniconda3/envs/worker/lib/python3.12/site-packages/airflow/utils/operator_helpers.py", line 252, in run
    return self.func(*args, **kwargs)
           ^^^^^^^^^^^^^^^^^^^^^^^^^^
  File "/home/lenovo/miniconda3/envs/worker/lib/python3.12/site-packages/airflow/models/baseoperator.py", line 422, in wrapper
    return func(self, *args, **kwargs)
           ^^^^^^^^^^^^^^^^^^^^^^^^^^^
  File "/home/lenovo/miniconda3/envs/worker/lib/python3.12/site-packages/airflow/operators/python.py", line 238, in execute
    return_value = self.execute_callable()
                   ^^^^^^^^^^^^^^^^^^^^^^^
  File "/home/lenovo/miniconda3/envs/worker/lib/python3.12/site-packages/airflow/operators/python.py", line 256, in execute_callable
    return runner.run(*self.op_args, **self.op_kwargs)
           ^^^^^^^^^^^^^^^^^^^^^^^^^^^^^^^^^^^^^^^^^^^
  File "/home/lenovo/miniconda3/envs/worker/lib/python3.12/site-packages/airflow/utils/operator_helpers.py", line 252, in run
    return self.func(*args, **kwargs)
           ^^^^^^^^^^^^^^^^^^^^^^^^^^
  File "/home/lenovo/airflow/dags/Scraping.py", line 59, in espera
    time.sleep(60)
  File "/home/lenovo/miniconda3/envs/worker/lib/python3.12/site-packages/airflow/models/taskinstance.py", line 3095, in signal_handler
    raise AirflowTaskTerminated("Task received SIGTERM signal")
airflow.exceptions.AirflowTaskTerminated: Task received SIGTERM signal

During handling of the above exception, another exception occurred:

Traceback (most recent call last):
  File "/home/lenovo/miniconda3/envs/worker/lib/python3.12/site-packages/sqlalchemy/engine/base.py", line 1910, in _execute_context
    self.dialect.do_execute(
  File "/home/lenovo/miniconda3/envs/worker/lib/python3.12/site-packages/sqlalchemy/engine/default.py", line 736, in do_execute
    cursor.execute(statement, parameters)
sqlite3.IntegrityError: FOREIGN KEY constraint failed

The above exception was the direct cause of the following exception:

Traceback (most recent call last):
  File "/home/lenovo/miniconda3/envs/worker/lib/python3.12/site-packages/airflow/task/task_runner/standard_task_runner.py", line 117, in _start_by_fork
    ret = args.func(args, dag=self.dag)
          ^^^^^^^^^^^^^^^^^^^^^^^^^^^^^
  File "/home/lenovo/miniconda3/envs/worker/lib/python3.12/site-packages/airflow/cli/cli_config.py", line 49, in command
    return func(*args, **kwargs)
           ^^^^^^^^^^^^^^^^^^^^^
  File "/home/lenovo/miniconda3/envs/worker/lib/python3.12/site-packages/airflow/utils/cli.py", line 116, in wrapper
    return f(*args, **kwargs)
           ^^^^^^^^^^^^^^^^^^
  File "/home/lenovo/miniconda3/envs/worker/lib/python3.12/site-packages/airflow/cli/commands/task_command.py", line 483, in task_run
    task_return_code = _run_task_by_selected_method(args, _dag, ti)
                       ^^^^^^^^^^^^^^^^^^^^^^^^^^^^^^^^^^^^^^^^^^^^
  File "/home/lenovo/miniconda3/envs/worker/lib/python3.12/site-packages/airflow/cli/commands/task_command.py", line 256, in _run_task_by_selected_method
    return _run_raw_task(args, ti)
           ^^^^^^^^^^^^^^^^^^^^^^^
  File "/home/lenovo/miniconda3/envs/worker/lib/python3.12/site-packages/airflow/cli/commands/task_command.py", line 341, in _run_raw_task
    return ti._run_raw_task(
           ^^^^^^^^^^^^^^^^^
  File "/home/lenovo/miniconda3/envs/worker/lib/python3.12/site-packages/airflow/utils/session.py", line 97, in wrapper
    return func(*args, session=session, **kwargs)
           ^^^^^^^^^^^^^^^^^^^^^^^^^^^^^^^^^^^^^^
  File "/home/lenovo/miniconda3/envs/worker/lib/python3.12/site-packages/airflow/models/taskinstance.py", line 3005, in _run_raw_task
    return _run_raw_task(
           ^^^^^^^^^^^^^^
  File "/home/lenovo/miniconda3/envs/worker/lib/python3.12/site-packages/airflow/models/taskinstance.py", line 327, in _run_raw_task
    ti.handle_failure(e, test_mode, context, session=session)
  File "/home/lenovo/miniconda3/envs/worker/lib/python3.12/site-packages/airflow/utils/session.py", line 94, in wrapper
    return func(*args, **kwargs)
           ^^^^^^^^^^^^^^^^^^^^^
  File "/home/lenovo/miniconda3/envs/worker/lib/python3.12/site-packages/airflow/models/taskinstance.py", line 3428, in handle_failure
    _handle_failure(
  File "/home/lenovo/miniconda3/envs/worker/lib/python3.12/site-packages/airflow/utils/session.py", line 94, in wrapper
    return func(*args, **kwargs)
           ^^^^^^^^^^^^^^^^^^^^^
  File "/home/lenovo/miniconda3/envs/worker/lib/python3.12/site-packages/airflow/api_internal/internal_api_call.py", line 166, in wrapper
    return func(*args, **kwargs)
           ^^^^^^^^^^^^^^^^^^^^^
  File "/home/lenovo/miniconda3/envs/worker/lib/python3.12/site-packages/airflow/models/taskinstance.py", line 1243, in _handle_failure
    TaskInstance.save_to_db(failure_context["ti"], session)
  File "/home/lenovo/miniconda3/envs/worker/lib/python3.12/site-packages/airflow/api_internal/internal_api_call.py", line 166, in wrapper
    return func(*args, **kwargs)
           ^^^^^^^^^^^^^^^^^^^^^
  File "/home/lenovo/miniconda3/envs/worker/lib/python3.12/site-packages/airflow/utils/session.py", line 94, in wrapper
    return func(*args, **kwargs)
           ^^^^^^^^^^^^^^^^^^^^^
  File "/home/lenovo/miniconda3/envs/worker/lib/python3.12/site-packages/airflow/models/taskinstance.py", line 3400, in save_to_db
    session.flush()
  File "/home/lenovo/miniconda3/envs/worker/lib/python3.12/site-packages/sqlalchemy/orm/session.py", line 3449, in flush
    self._flush(objects)
  File "/home/lenovo/miniconda3/envs/worker/lib/python3.12/site-packages/sqlalchemy/orm/session.py", line 3588, in _flush
    with util.safe_reraise():
         ^^^^^^^^^^^^^^^^^^^
  File "/home/lenovo/miniconda3/envs/worker/lib/python3.12/site-packages/sqlalchemy/util/langhelpers.py", line 70, in __exit__
    compat.raise_(
  File "/home/lenovo/miniconda3/envs/worker/lib/python3.12/site-packages/sqlalchemy/util/compat.py", line 211, in raise_
    raise exception
  File "/home/lenovo/miniconda3/envs/worker/lib/python3.12/site-packages/sqlalchemy/orm/session.py", line 3549, in _flush
    flush_context.execute()
  File "/home/lenovo/miniconda3/envs/worker/lib/python3.12/site-packages/sqlalchemy/orm/unitofwork.py", line 456, in execute
    rec.execute(self)
  File "/home/lenovo/miniconda3/envs/worker/lib/python3.12/site-packages/sqlalchemy/orm/unitofwork.py", line 630, in execute
    util.preloaded.orm_persistence.save_obj(
  File "/home/lenovo/miniconda3/envs/worker/lib/python3.12/site-packages/sqlalchemy/orm/persistence.py", line 245, in save_obj
    _emit_insert_statements(
  File "/home/lenovo/miniconda3/envs/worker/lib/python3.12/site-packages/sqlalchemy/orm/persistence.py", line 1238, in _emit_insert_statements
    result = connection._execute_20(
             ^^^^^^^^^^^^^^^^^^^^^^^
  File "/home/lenovo/miniconda3/envs/worker/lib/python3.12/site-packages/sqlalchemy/engine/base.py", line 1710, in _execute_20
    return meth(self, args_10style, kwargs_10style, execution_options)
           ^^^^^^^^^^^^^^^^^^^^^^^^^^^^^^^^^^^^^^^^^^^^^^^^^^^^^^^^^^^
  File "/home/lenovo/miniconda3/envs/worker/lib/python3.12/site-packages/sqlalchemy/sql/elements.py", line 334, in _execute_on_connection
    return connection._execute_clauseelement(
           ^^^^^^^^^^^^^^^^^^^^^^^^^^^^^^^^^^
  File "/home/lenovo/miniconda3/envs/worker/lib/python3.12/site-packages/sqlalchemy/engine/base.py", line 1577, in _execute_clauseelement
    ret = self._execute_context(
          ^^^^^^^^^^^^^^^^^^^^^^
  File "/home/lenovo/miniconda3/envs/worker/lib/python3.12/site-packages/sqlalchemy/engine/base.py", line 1953, in _execute_context
    self._handle_dbapi_exception(
  File "/home/lenovo/miniconda3/envs/worker/lib/python3.12/site-packages/sqlalchemy/engine/base.py", line 2134, in _handle_dbapi_exception
    util.raise_(
  File "/home/lenovo/miniconda3/envs/worker/lib/python3.12/site-packages/sqlalchemy/util/compat.py", line 211, in raise_
    raise exception
  File "/home/lenovo/miniconda3/envs/worker/lib/python3.12/site-packages/sqlalchemy/engine/base.py", line 1910, in _execute_context
    self.dialect.do_execute(
  File "/home/lenovo/miniconda3/envs/worker/lib/python3.12/site-packages/sqlalchemy/engine/default.py", line 736, in do_execute
    cursor.execute(statement, parameters)
sqlalchemy.exc.IntegrityError: (sqlite3.IntegrityError) FOREIGN KEY constraint failed
[SQL: INSERT INTO task_fail (task_id, dag_id, run_id, map_index, start_date, end_date, duration) VALUES (?, ?, ?, ?, ?, ?, ?)]
[parameters: ('wait_1', 'Scraping', 'scheduled__2025-04-20T00:00:00+00:00', -1, '2025-04-21 06:03:07.117506', '2025-04-21 06:03:19.293924', 12)]
(Background on this error at: https://sqlalche.me/e/14/gkpj)
[2025-04-21T03:03:19.370-0300] {process_utils.py:80} INFO - Process psutil.Process(pid=30004, status='terminated', exitcode=1, started='03:03:06') (30004) terminated with exit code 1
[2025-04-21T03:05:16.957-0300] {local_task_job_runner.py:123} INFO - ::group::Pre task execution logs
[2025-04-21T03:05:16.984-0300] {taskinstance.py:2613} INFO - Dependencies all met for dep_context=non-requeueable deps ti=<TaskInstance: Scraping.wait_1 scheduled__2025-04-20T00:00:00+00:00 [queued]>
[2025-04-21T03:05:16.994-0300] {taskinstance.py:2613} INFO - Dependencies all met for dep_context=requeueable deps ti=<TaskInstance: Scraping.wait_1 scheduled__2025-04-20T00:00:00+00:00 [queued]>
[2025-04-21T03:05:16.994-0300] {taskinstance.py:2866} INFO - Starting attempt 1 of 2
[2025-04-21T03:05:17.019-0300] {taskinstance.py:2889} INFO - Executing <Task(PythonOperator): wait_1> on 2025-04-20 00:00:00+00:00
[2025-04-21T03:05:17.024-0300] {standard_task_runner.py:72} INFO - Started process 30586 to run task
[2025-04-21T03:05:17.027-0300] {standard_task_runner.py:104} INFO - Running: ['airflow', 'tasks', 'run', 'Scraping', 'wait_1', 'scheduled__2025-04-20T00:00:00+00:00', '--job-id', '56', '--raw', '--subdir', 'DAGS_FOLDER/Scraping.py', '--cfg-path', '/tmp/tmprj_ahrqm']
[2025-04-21T03:05:17.029-0300] {standard_task_runner.py:105} INFO - Job 56: Subtask wait_1
[2025-04-21T03:05:17.082-0300] {task_command.py:467} INFO - Running <TaskInstance: Scraping.wait_1 scheduled__2025-04-20T00:00:00+00:00 [running]> on host DESKTOP-1GIT60U.
[2025-04-21T03:05:17.191-0300] {taskinstance.py:3132} INFO - Exporting env vars: AIRFLOW_CTX_DAG_EMAIL='airflow@example.com' AIRFLOW_CTX_DAG_OWNER='airflow' AIRFLOW_CTX_DAG_ID='Scraping' AIRFLOW_CTX_TASK_ID='wait_1' AIRFLOW_CTX_EXECUTION_DATE='2025-04-20T00:00:00+00:00' AIRFLOW_CTX_TRY_NUMBER='1' AIRFLOW_CTX_DAG_RUN_ID='scheduled__2025-04-20T00:00:00+00:00'
[2025-04-21T03:05:17.193-0300] {taskinstance.py:731} INFO - ::endgroup::
[2025-04-21T03:06:21.064-0300] {python.py:240} INFO - Done. Returned value was: None
[2025-04-21T03:06:21.072-0300] {taskinstance.py:340} INFO - ::group::Post task execution logs
[2025-04-21T03:06:21.072-0300] {taskinstance.py:352} INFO - Marking task as SUCCESS. dag_id=Scraping, task_id=wait_1, run_id=scheduled__2025-04-20T00:00:00+00:00, execution_date=20250420T000000, start_date=20250421T060516, end_date=20250421T060621
[2025-04-21T03:06:21.141-0300] {local_task_job_runner.py:266} INFO - Task exited with return code 0
[2025-04-21T03:06:21.162-0300] {taskinstance.py:3895} INFO - 1 downstream tasks scheduled from follow-on schedule check
[2025-04-21T03:06:21.176-0300] {local_task_job_runner.py:245} INFO - ::endgroup::
[2025-04-21T13:38:59.112-0300] {local_task_job_runner.py:123} INFO - ::group::Pre task execution logs
[2025-04-21T13:38:59.129-0300] {taskinstance.py:2613} INFO - Dependencies all met for dep_context=non-requeueable deps ti=<TaskInstance: Scraping.wait_1 scheduled__2025-04-20T00:00:00+00:00 [queued]>
[2025-04-21T13:38:59.143-0300] {taskinstance.py:2613} INFO - Dependencies all met for dep_context=requeueable deps ti=<TaskInstance: Scraping.wait_1 scheduled__2025-04-20T00:00:00+00:00 [queued]>
[2025-04-21T13:38:59.143-0300] {taskinstance.py:2866} INFO - Starting attempt 1 of 2
[2025-04-21T13:38:59.168-0300] {taskinstance.py:2889} INFO - Executing <Task(PythonOperator): wait_1> on 2025-04-20 00:00:00+00:00
[2025-04-21T13:38:59.173-0300] {standard_task_runner.py:72} INFO - Started process 73445 to run task
[2025-04-21T13:38:59.177-0300] {standard_task_runner.py:104} INFO - Running: ['airflow', 'tasks', 'run', 'Scraping', 'wait_1', 'scheduled__2025-04-20T00:00:00+00:00', '--job-id', '98', '--raw', '--subdir', 'DAGS_FOLDER/Ifood_case.py', '--cfg-path', '/tmp/tmp4w80h5ry']
[2025-04-21T13:38:59.179-0300] {standard_task_runner.py:105} INFO - Job 98: Subtask wait_1
[2025-04-21T13:38:59.230-0300] {task_command.py:467} INFO - Running <TaskInstance: Scraping.wait_1 scheduled__2025-04-20T00:00:00+00:00 [running]> on host DESKTOP-1GIT60U.
[2025-04-21T13:38:59.301-0300] {taskinstance.py:3132} INFO - Exporting env vars: AIRFLOW_CTX_DAG_EMAIL='airflow@example.com' AIRFLOW_CTX_DAG_OWNER='airflow' AIRFLOW_CTX_DAG_ID='Scraping' AIRFLOW_CTX_TASK_ID='wait_1' AIRFLOW_CTX_EXECUTION_DATE='2025-04-20T00:00:00+00:00' AIRFLOW_CTX_TRY_NUMBER='1' AIRFLOW_CTX_DAG_RUN_ID='scheduled__2025-04-20T00:00:00+00:00'
[2025-04-21T13:38:59.302-0300] {taskinstance.py:731} INFO - ::endgroup::
[2025-04-21T13:39:59.316-0300] {python.py:240} INFO - Done. Returned value was: None
[2025-04-21T13:39:59.321-0300] {taskinstance.py:340} INFO - ::group::Post task execution logs
[2025-04-21T13:39:59.322-0300] {taskinstance.py:352} INFO - Marking task as SUCCESS. dag_id=Scraping, task_id=wait_1, run_id=scheduled__2025-04-20T00:00:00+00:00, execution_date=20250420T000000, start_date=20250421T163859, end_date=20250421T163959
[2025-04-21T13:39:59.361-0300] {local_task_job_runner.py:266} INFO - Task exited with return code 0
[2025-04-21T13:39:59.373-0300] {taskinstance.py:3895} INFO - 1 downstream tasks scheduled from follow-on schedule check
[2025-04-21T13:39:59.381-0300] {local_task_job_runner.py:245} INFO - ::endgroup::
